<?xml version="1.0" encoding="utf-8"?>
<!-- =================================================================================== -->
<!-- |    This document was autogenerated by xacro from omav.urdf.xacro                | -->
<!-- |    EDITING THIS FILE BY HAND IS NOT RECOMMENDED                                 | -->
<!-- =================================================================================== -->
<robot name="ouzel">
  <link name="odom"/>
  <link name="ouzel">
    <inertial>
      <mass value="5.0"/>
      <origin rpy="0 0 0" xyz="0 0 0"/>
      <inertia ixx="0.12" ixy="0" ixz="0" iyy="0.14" iyz="0" izz="0.18"/>
    </inertial>
    <visual>
      <origin rpy="0 0 0" xyz="0 0 0"/>
      <geometry>
        <mesh filename="/home/studigem/catkin_ws/src/sampling_based_control/mppi_examples/mppi_omav_raisim/data/meshes/ouzel_inspection_full.stl"/>
      </geometry>
      <material name="">
        <color rgba="1 1 1 1"/>
      </material>
    </visual>
  </link>
  <joint name="odom_drone" type="floating">
    <origin rpy="0 0 0" xyz="0 0 0"/>
    <parent link="odom"/>
    <child link="ouzel"/>
  </joint>
</robot>

