<?xml version="1.0" encoding="utf-8"?>
<!-- =================================================================================== -->
<!-- |    This document was autogenerated by xacro from button.urdf.xacro              | -->
<!-- |    EDITING THIS FILE BY HAND IS NOT RECOMMENDED                                 | -->
<!-- =================================================================================== -->
<robot name="cube">
  <link name="world"/>
  <joint name="odom_to_world" type="fixed">
    <parent link="world"/>
    <child link="odom_button"/>
    <origin rpy="0 0 0" xyz="2.0 0.0 1.0"/>
  </joint>
  <link name="odom_button">
    <inertial>
      <mass value="0.5"/>
      <origin rpy="0 0 0" xyz="0 0 0"/>
      <inertia ixx="0.12" ixy="0" ixz="0" iyy="0.14" iyz="0" izz="0.18"/>
    </inertial>
  </link>
  <joint name="articulation_joint" type="prismatic">
    <parent link="odom_button"/>
    <child link="button_x"/>
    <origin rpy="0 0 0" xyz="0.0 0.0 0.0"/>
    <axis xyz="1 0 0"/>
    <limit effort="1000.0" lower="-100" upper="100" velocity="5.0"/>
    <dynamics damping="1" spring_mount="0 0 0" stiffness="10.0"/>
  </joint>
  <link name="button_x">
    <inertial>
      <mass value="0.5"/>
      <origin rpy="0 0 0" xyz="0 0 0"/>
      <inertia ixx="0.12" ixy="0" ixz="0" iyy="0.14" iyz="0" izz="0.18"/>
    </inertial>
    <collision>
      <origin rpy="0 0 0" xyz="0 0 0.0"/>
      <geometry>
        <box size="0.3 0.3 0.3"/>
      </geometry>
      <material name="">
        <contact name="rubber"/>
      </material>
    </collision>
    <visual>
      <origin rpy="0 0 0" xyz="0 0 0"/>
      <geometry>
        <box size="0.3 0.3 0.3"/>
      </geometry>
      <material name="">
        <color rgba="1 1 1 1"/>
      </material>
    </visual>
  </link>
</robot>

