<?xml version="1.0" ?>
<!-- =================================================================================== -->
<!-- |    This document was autogenerated by xacro from omav_raisim_hook.urdf.xacro    | -->
<!-- |    EDITING THIS FILE BY HAND IS NOT RECOMMENDED                                 | -->
<!-- =================================================================================== -->
<robot name="omav_raisim_hook">
  <!-- [m] -->
  <!-- [m] -->
  <link name="world"/>
  <link name="odom"/>
  <joint name="odom_to_world" type="fixed">
    <parent link="world"/>
    <child link="odom"/>
  </joint>
  <joint name="odom_to_omav_x" type="prismatic">
    <parent link="odom"/>
    <child link="omav_x"/>
    <origin rpy="0 0 0" xyz="0.0 0.0 0.0"/>
    <axis xyz="1 0 0"/>
    <limit effort="1000.0" lower="-100" upper="100" velocity="5.0"/>
  </joint>
  <link name="omav_x"/>
  <joint name="omav_x_to_omav_y" type="prismatic">
    <parent link="omav_x"/>
    <child link="omav_y"/>
    <origin rpy="0 0 0" xyz="0.0 0.0 0.0"/>
    <axis xyz="0 1 0"/>
    <limit effort="1000.0" lower="-100" upper="100" velocity="5.0"/>
  </joint>
  <link name="omav_y"/>
  <joint name="omav_y_to_omav_z" type="prismatic">
    <parent link="omav_y"/>
    <child link="omav_z"/>
    <origin rpy="0 0 0" xyz="0.0 0.0 0.0"/>
    <axis xyz="0 0 1"/>
    <limit effort="1000.0" lower="-100" upper="100" velocity="5.0"/>
  </joint>
  <link name="omav_z"/>
  <joint name="omav_z_to_omav" type="spherical">
    <parent link="omav_z"/>
    <child link="omav"/>
    <origin rpy="0 0 0" xyz="0.0 0.0 0.0"/>
    <axis xyz="0 1 0"/>
  </joint>
  <link name="omav">
    <inertial>
      <mass value="4.337"/>
      <origin rpy="0 0 0" xyz="0 0 0"/>
      <inertia ixx="0.078359" ixy="0" ixz="0" iyy="0.081797" iyz="0" izz="0.153355"/>
    </inertial>
    <collision>
      <origin rpy="0 0 0" xyz="0 0 0"/>
      <geometry>
        <cylinder length="0.3" radius="0.2"/>
      </geometry>
    </collision>
    <visual>
      <origin rpy="0 0 0" xyz="0 0 0"/>
      <geometry>
        <cylinder length="0.3" radius="0.2"/>
      </geometry>
      <material name="">
        <color rgba="1 1 1 1"/>
      </material>
    </visual>
  </link>
  <joint name="omav_to_rod" type="fixed">
    <parent link="omav"/>
    <child link="rod"/>
    <origin rpy="1.5708 0 0" xyz="0.3025 0.0 0.0"/>
  </joint>
  <link name="rod">
    <collision>
      <origin rpy="0 1.5708 0" xyz="0 0 0"/>
      <geometry>
        <cylinder length="0.605" radius="0.0075"/>
        <!-- <box size="${manipulator_radius*2} ${manipulator_radius*2} ${manipulator_length}"/> -->
      </geometry>
      <material name="">
        <contact name="steel"/>
      </material>
    </collision>
    <visual>
      <origin rpy="0 1.5708 0" xyz="0 0 0"/>
      <geometry>
        <cylinder length="0.605" radius="0.0075"/>
        <!-- <box size="${manipulator_radius*2} ${manipulator_radius*2} ${manipulator_length}"/> -->
      </geometry>
      <material name="">
        <color rgba="1 1 1 1"/>
      </material>
    </visual>
  </link>
  <joint name="rod_to_hook" type="fixed">
    <parent link="rod"/>
    <child link="hook"/>
    <origin rpy="0 0 0" xyz="0.3025 0.0 -0.02"/>
  </joint>
  <!-- <link name="tip">
        <collision>
            <origin rpy="0 0 0" xyz="0 0 0"/>
            <geometry>
                <sphere radius="${tool_radius}"/>
            </geometry>
            <material name="">
                <contact name="steel"/>
            </material>
        </collision>
        <visual>
            <origin rpy="0 0 0" xyz="0 0.0 0"/>
            <geometry>
                <sphere radius="${tool_radius}"/>
            </geometry>
            <material name="">
                <color rgba="1 1 1 1"/>
            </material>
        </visual>
    </link> -->
  <!--
    <joint name="tip_to_thick" type="fixed">
        <parent link="tip"/>
        <child link="thick"/>
        <origin rpy="0 0 0" xyz="-0.04 0.0 0.0"/>
    </joint>

    <link name="thick">
        <collision>
            <origin rpy="0 1.5708 0" xyz="0 0 0"/>
            <geometry>
                <cylinder radius="0.015" length="0.095"/>
            </geometry>
            <material name="">
                <contact name="steel"/>
            </material>
        </collision>
        <visual>
            <origin rpy="0 1.5708 0" xyz="0 0 0"/>
            <geometry>
                <cylinder radius="0.015" length="0.095"/>
            </geometry>
            <material name="">
                <color rgba="1 1 1 1"/>
            </material>
        </visual>
    </link>
-->
  <!-- <joint name="tip_to_hook" type="fixed">
        <parent link="tip"/>
        <child link="hook"/>
        <origin rpy="0 0 0" xyz="0.0 0.0 -${tool_length/2}"/>
    </joint> -->
  <link name="hook">
    <collision>
      <origin rpy="0 0 0" xyz="0 0 0"/>
      <geometry>
        <cylinder length="0.04" radius="0.0075"/>
        <!-- <box size="${tool_radius*2} ${tool_radius*2} ${tool_length}"/> -->
      </geometry>
      <material name="">
        <contact name="steel"/>
      </material>
    </collision>
    <visual>
      <origin rpy="0 0 0" xyz="0 0 0"/>
      <geometry>
        <cylinder length="0.04" radius="0.0075"/>
        <!-- <box size="${tool_radius*2} ${tool_radius*2} ${tool_length}"/> -->
      </geometry>
      <material name="">
        <color rgba="1 1 1 1"/>
      </material>
    </visual>
  </link>
</robot>
