<?xml version="1.0" encoding="utf-8"?>
<!-- =================================================================================== -->
<!-- |    This document was autogenerated by xacro from omav_raisim_hook.urdf.xacro    | -->
<!-- |    EDITING THIS FILE BY HAND IS NOT RECOMMENDED                                 | -->
<!-- =================================================================================== -->
<robot name="omav_raisim_hook">
  <link name="world"/>
  <link name="odom"/>
  <joint name="odom_to_world" type="fixed">
    <parent link="world"/>
    <child link="odom"/>
  </joint>
  <joint name="odom_to_omav_x" type="prismatic">
    <parent link="odom"/>
    <child link="omav_x"/>
    <origin rpy="0 0 0" xyz="0.0 0.0 0.0"/>
    <axis xyz="1 0 0"/>
    <limit effort="1000.0" lower="-100" upper="100" velocity="5.0"/>
  </joint>
  <link name="omav_x"/>
  <joint name="omav_x_to_omav_y" type="prismatic">
    <parent link="omav_x"/>
    <child link="omav_y"/>
    <origin rpy="0 0 0" xyz="0.0 0.0 0.0"/>
    <axis xyz="0 1 0"/>
    <limit effort="1000.0" lower="-100" upper="100" velocity="5.0"/>
  </joint>
  <link name="omav_y"/>
  <joint name="omav_y_to_omav_z" type="prismatic">
    <parent link="omav_y"/>
    <child link="omav_z"/>
    <origin rpy="0 0 0" xyz="0.0 0.0 0.0"/>
    <axis xyz="0 0 1"/>
    <limit effort="1000.0" lower="-100" upper="100" velocity="5.0"/>
  </joint>
  <link name="omav_z"/>
  <joint name="omav_z_to_omav" type="spherical">
    <parent link="omav_z"/>
    <child link="omav"/>
    <origin rpy="0 0 0" xyz="0.0 0.0 0.0"/>
    <axis xyz="0 1 0"/>
  </joint>
  <link name="omav">
    <inertial>
      <mass value="5.0"/>
      <origin rpy="0 0 0" xyz="0 0 0"/>
      <inertia ixx="0.12" ixy="0" ixz="0" iyy="0.14" iyz="0" izz="0.18"/>
    </inertial>
    <collision>
      <origin rpy="0 0 0" xyz="0 0 0"/>
      <geometry>
        <cylinder length="0.3" radius="0.2"/>
      </geometry>
    </collision>
    <visual>
      <origin rpy="0 0 0" xyz="0 0 0"/>
      <geometry>
        <cylinder length="0.3" radius="0.2"/>
      </geometry>
      <material name="">
        <color rgba="1 1 1 1"/>
      </material>
    </visual>
  </link>
  <joint name="omav_to_rod" type="fixed">
    <parent link="omav"/>
    <child link="rod"/>
    <origin rpy="0 0 0" xyz="0.275 0.0 0.05"/>
  </joint>
  <link name="rod">
    <collision>
      <origin rpy="0 1.5708 0" xyz="0 0 0"/>
      <geometry>
        <cylinder length="0.54" radius="0.0075"/>
      </geometry>
      <material name="">
        <contact name="rubber"/>
      </material>
    </collision>
    <visual>
      <origin rpy="0 1.5708 0" xyz="0 0 0"/>
      <geometry>
        <cylinder length="0.54" radius="0.0075"/>
      </geometry>
      <material name="">
        <color rgba="1 1 1 1"/>
      </material>
    </visual>
  </link>
  <joint name="rod_to_tip" type="fixed">
    <parent link="rod"/>
    <child link="tip"/>
    <origin rpy="0 0 0" xyz="0.27 0.0 0.0"/>
  </joint>
  <link name="tip">
    <collision>
      <origin rpy="0 0 0" xyz="0 0 0"/>
      <geometry>
        <sphere radius="0.0075"/>
      </geometry>
      <material name="">
        <contact name="rubber"/>
      </material>
    </collision>
    <visual>
      <origin rpy="0 0 0" xyz="0 0.0 0"/>
      <geometry>
        <sphere radius="0.0075"/>
      </geometry>
      <material name="">
        <color rgba="1 1 1 1"/>
      </material>
    </visual>
  </link>
  <joint name="tip_to_hook" type="fixed">
    <parent link="tip"/>
    <child link="hook"/>
    <origin rpy="0 0 0" xyz="0.0 0.0 -0.025"/>
  </joint>
  <link name="hook">
    <collision>
      <origin rpy="0 0 0" xyz="0 0 0"/>
      <geometry>
        <cylinder length="0.05" radius="0.0075"/>
      </geometry>
      <material name="">
        <contact name="rubber"/>
      </material>
    </collision>
    <visual>
      <origin rpy="0 0 0" xyz="0 0 0"/>
      <geometry>
        <cylinder length="0.05" radius="0.0075"/>
      </geometry>
      <material name="">
        <color rgba="1 1 1 1"/>
      </material>
    </visual>
  </link>
</robot>

