<?xml version='1.0' encoding='ASCII'?>
<!-- NOTE: this should be identical to the object model of the affordance node -->
<robot name="11826" xmlns:xacro="http://www.ros.org/wiki/xacro" >
  <xacro:arg name="prefix" default=""/>
  <xacro:arg name="resources_directory" default=""/>
  <xacro:arg name="resources_prefix" default=""/>
  <xacro:property name="prefix" default="$(arg prefix)"/>
  <xacro:property name="resources_directory" default="$(arg resources_directory)"/>
  <xacro:property name="resources_prefix" default="$(arg resources_prefix)"/>
  <link name="world"/>
  <link name="base"/>
  <link name="${prefix}handle_link_2"/>
  <link name="${prefix}handle_link">
    <inertial>
      <origin xyz="0.0 0.0 0.0" rpy="0.0 -0.0 0.0"/>
      <mass value="3.0"/>
      <inertia ixx="0.4333886585" ixy="0.0" ixz="0.0" iyy="0.39146708384" iyz="0.0" izz="0.042168942339999994"/>
    </inertial>
    <visual>
      <geometry>
        <mesh filename="${resources_directory}${resources_prefix}textured_objs/original-4.obj" scale="0.4538303702144554 0.4538303702144554 0.4538303702144554"/>
      </geometry>
      <origin xyz="0.23330056661655543 0.2226204113200439 -0.19163586347627987" rpy="0.0 -0.0 0.0"/>
    </visual>
    <visual>
      <geometry>
        <mesh filename="${resources_directory}${resources_prefix}textured_objs/original-3.obj" scale="0.4538303702144554 0.4538303702144554 0.4538303702144554"/>
      </geometry>
      <origin xyz="0.23330056661655543 0.2226204113200439 -0.19163586347627987" rpy="0.0 -0.0 0.0"/>
    </visual>
    <visual>
      <geometry>
        <mesh filename="${resources_directory}${resources_prefix}textured_objs/original-2.obj" scale="0.4538303702144554 0.4538303702144554 0.4538303702144554"/>
      </geometry>
      <origin xyz="0.23330056661655543 0.2226204113200439 -0.19163586347627987" rpy="0.0 -0.0 0.0"/>
    </visual>
    <collision>
      <geometry>
        <mesh filename="${resources_directory}${resources_prefix}consolidated_collision_meshes/link_2.obj" scale="0.4538303702144554 0.4538303702144554 0.4538303702144554"/>
      </geometry>
      <origin xyz="0.0 0.0 0.0" rpy="0.0 -0.0 0.0"/>
    </collision>
  </link>
  <link name="${prefix}link_3">
    <visual>
      <geometry>
        <mesh filename="${resources_directory}${resources_prefix}consolidated_collision_meshes/link_3.obj" scale="0.4538303702144554 0.4538303702144554 0.4538303702144554"/>
      </geometry>
      <origin xyz="0.0 0.0 0.0" rpy="0.0 -0.0 0.0"/>
    </visual>
    <collision>
      <geometry>
        <mesh filename="${resources_directory}${resources_prefix}consolidated_collision_meshes/link_3.obj" scale="0.4538303702144554 0.4538303702144554 0.4538303702144554"/>
      </geometry>
      <origin xyz="0.0 0.0 0.0" rpy="0.0 -0.0 0.0"/>
    </collision>
  </link>
  <joint name="fixed" type="fixed">
    <parent link="world"/>
    <child link="base"/>
    <origin xyz="1.5 0.5 0.85" rpy="0.0 -0.0 0.0"/>
    <axis xyz="1.0 0.0 0.0"/>
  </joint>
  <joint name="articulation_joint" type="revolute">
    <parent link="${prefix}link_3"/>
    <child link="${prefix}handle_link"/>
    <origin xyz="-0.23330056661655543 -0.2226204113200439 0.19163586347627987" rpy="0.0 -0.0 0.0"/>
    <axis xyz="1.0 0.0 0.0"/>
    <limit effort="1000.0" velocity="1.0" lower="0.0" upper="1.5707963267948966"/>
    <dynamics damping="20.0" friction="40.0"/>
  </joint>
  <joint name="${prefix}handle_joint" type="fixed">
    <parent link="${prefix}handle_link"/>
    <child link="${prefix}handle_link_2"/>
    <origin xyz="0 0 0" rpy="0.0 0.0 0.0"/>
  </joint>
  <joint name="${prefix}joint_3" type="fixed">
    <parent link="base"/>
    <child link="${prefix}link_3"/>
    <origin xyz="0.0 0.0 0.0" rpy="1.570796326794897 -0.0 -1.570796326794897"/>
    <axis xyz="1.0 0.0 0.0"/>
  </joint>
</robot>
