<?xml version="1.0" ?>
<!-- =================================================================================== -->
<!-- |    This document was autogenerated by xacro from dishwasher_door.urdf.xacro     | -->
<!-- |    EDITING THIS FILE BY HAND IS NOT RECOMMENDED                                 | -->
<!-- =================================================================================== -->
<robot name="dishwasher_door">
  <!-- Should be less then h - h_handle - h_bottom -->
  <link name="base_link">
    <origin rpy="0 0 0" xyz="0 0 0"/>
  </link>
  <link name="dishwasher_door">
    <inertial>
      <mass value="3"/>
      <inertia ixx="0.000247" ixy="0" ixz="0" iyy="0.077989" iyz="0" izz="0.457670"/>
      <origin rpy="0 0 0" xyz="0 0 0"/>
    </inertial>
    <!--     <visual>
      <origin xyz="0 -0.08 -0.13" rpy="0 0 1.57"/>
      <geometry>
        <mesh filename="file:///home/giuseppe/catkin_ws/src/sampling_based_control/mppi_examples/mppi_manipulation/data/objects/door.obj" scale="1 1 1"/>
      </geometry>
      <material name="white">
        <color rgba="1. 1. 1. 1."/>
      </material>
    </visual> -->
    <!-- Back side -->
    <visual>
      <origin rpy="0 0 0.0" xyz="0 0 0.325"/>
      <geometry>
        <box size="0.03 0.65 0.65"/>
      </geometry>
      <material name="white">
        <color rgba="1.0 1.0 1.0 1.0"/>
      </material>
    </visual>
    <collision>
      <origin rpy="0 0 0.0" xyz="0 0 0.325"/>
      <geometry>
        <box size="0.03 0.65 0.65"/>
      </geometry>
    </collision>
    <!-- Left part -->
    <visual>
      <origin rpy="0 0 0" xyz="0.03 -0.225 0.325"/>
      <geometry>
        <box size="0.03 0.2 0.65"/>
      </geometry>
      <material name="white">
        <color rgba="1.0 1.0 1.0 1.0"/>
      </material>
    </visual>
    <collision>
      <origin rpy="0 0 0" xyz="0.03 -0.225 0.325"/>
      <geometry>
        <box size="0.03 0.2 0.65"/>
      </geometry>
    </collision>
    <!-- Right part -->
    <visual>
      <origin rpy="0 0 0" xyz="0.03 0.225 0.325"/>
      <geometry>
        <box size="0.03 0.2 0.65"/>
      </geometry>
      <material name="white">
        <color rgba="1.0 1.0 1.0 1.0"/>
      </material>
    </visual>
    <collision>
      <origin rpy="0 0 0" xyz="0.03 0.225 0.325"/>
      <geometry>
        <box size="0.03 0.2 0.65"/>
      </geometry>
    </collision>
    <!-- Upper part -->
    <visual>
      <origin rpy="0 0 0" xyz="0.04 0 0.615"/>
      <geometry>
        <box size="0.01 0.25 0.07000000000000003"/>
      </geometry>
      <material name="white">
        <color rgba="1.0 1.0 1.0 1.0"/>
      </material>
    </visual>
    <collision>
      <origin rpy="0 0 0" xyz="0.04 0 0.615"/>
      <geometry>
        <box size="0.01 0.25 0.07000000000000003"/>
      </geometry>
    </collision>
    <!--  Bottom part-->
    <visual>
      <origin rpy="0 0 0" xyz="0.03 0 0.24"/>
      <geometry>
        <box size="0.03 0.25 0.48"/>
      </geometry>
      <material name="white">
        <color rgba="1.0 1.0 1.0 1.0"/>
      </material>
    </visual>
    <collision>
      <origin rpy="0 0 0" xyz="0.03 0 0.24"/>
      <geometry>
        <box size="0.03 0.25 0.48"/>
      </geometry>
    </collision>
    <!--  Handle intake-->
    <visual>
      <origin rpy="0 -0.3490658503988659 0" xyz="0.013803603521927936                     0                     0.5218543288894103"/>
      <geometry>
        <box size="0.03 0.25 0.1"/>
      </geometry>
      <material name="white">
        <color rgba="1.0 1.0 1.0 1.0"/>
      </material>
    </visual>
    <collision>
      <origin rpy="0 -0.3490658503988659 0" xyz="0.013803603521927936                     0                     0.5218543288894103"/>
      <geometry>
        <box size="0.03 0.25 0.1"/>
      </geometry>
    </collision>
    <!-- Upper closure -->
    <visual>
      <origin rpy="0 0 0" xyz="0.03 0 0.64"/>
      <geometry>
        <box size="0.03 0.25 0.02"/>
      </geometry>
      <material name="white">
        <color rgba="1.0 1.0 1.0 1.0"/>
      </material>
    </visual>
    <collision>
      <origin rpy="0 0 0" xyz="0.03 0 0.64"/>
      <geometry>
        <box size="0.03 0.25 0.02"/>
      </geometry>
    </collision>
    <!-- Intake flat rear -->
    <!--     <collision>
      <origin xyz="${w_back/2 + w_intake_rear/2} 0 ${(h + h_bottom)/2}" rpy="0 0 0"/>
      <geometry>
        <box size="${w_intake_rear} ${l_center} ${h - h_bottom}"/>
      </geometry>
    </collision> -->
  </link>
  <joint name="articulation_joint" type="revolute">
    <parent link="base_link"/>
    <child link="dishwasher_door"/>
    <axis xyz="0 1 0"/>
    <origin rpy="0 0 0" xyz="0 0.08 0.13"/>
    <dynamics damping="1" friction="0.01"/>
    <limit effort="100" lower="0" upper="1.57" velocity="10.0"/>
  </joint>
  <link name="handle_link"/>
  <joint name="handle_joint" type="fixed">
    <parent link="dishwasher_door"/>
    <child link="handle_link"/>
    <origin rpy="1.5708 0 0" xyz="0.0 0 0.53"/>
  </joint>
</robot>

